# 47장 에러 처리

## 47.1 에러 처리의 필요성

- 에러가 발생하지 않는 코드를 작성하는 것은 불가능하다.
- 따라서 에러에 대한 방치가 필요하다.
- 직접적인 에러가 아닌 예외적인 상황이 발생할 수도 있다.
- 예외적인 상황에 대한 대처가 없다면 에러로 이어질 수 있다.

## 47.2 try...catch...finally 문

- 에러 처리는 크게 두 가지가 존재한다.

1. 예외적인 상황이 발생하면 반환하는 값(null or -1)을 if문, 단축 평가, 옵셔널 체이닝을 통해 처리
2. 에러 처리 코드를 미리 등록해 두고 에러가 발생하면 에러 처리 코드로 전달하여 처리

> `try...catch...finally`을 통해 두 번째 방법이 가능하다.

```js
console.log("[Start]");

try {
  // 실행할 코드(에러가 발생할 가능성이 있는 코드)
  foo();
} catch (err) {
  // try 코드 블록에서 에러가 발생하면 이 코드 블록의 코드가 실행된다.
  // err에는 try 코드 블록에서 발생한 Error 객체가 전달된다.
  console.error(err); // ReferenceError: foo is not defined
} finally {
  // 에러 발생과 상관없이 반드시 한 번 실행된다.
  console.log("finally");
}

// try...catch...finally 문으로 에러를 처리하면 프로그램이 강제 종료되지 않는다.
console.log("[End]");
```

## 47.3 Error 객체

- Error 생성자 함수는 에러 객체를 생성한다.
- Error 생성자 함수에는 에러를 상세히 설명하는 에러 메시지를 인수로 전달할 수 있다.
- Error 생성자 함수가 생성한 에러 객체에는 message 프로퍼티와 stack 프로퍼티를 갖는다.
  - message 프로퍼티 : Error 생성자 함수에 인수로 전달한 에러 메세지
  - stack 프로퍼티 : 에러를 발생시킨 콜스택의 호출 정보를 나타내는 문자열이며 디버깅 목적으로 사용한다.
- 자바스크립트는 Error 생성자 함수를 포함해 7가지 에러 객체를 생성할 수 있는 Error 생성자 함수를 제공한다.

  | 생성자 함수    | 인스턴스                                                                       |
  | -------------- | ------------------------------------------------------------------------------ |
  | Error          | 일반적 에러 객체                                                               |
  | SyntaxError    | 자바스크립트 문법에 맞지 않는 문을 해설할 때 발생하는 에러 객체                |
  | ReferenceError | 참조할 수 없는 식별자를 참조했을 때 발생하는 에러 객체                         |
  | TypeError      | 피연산자 또는 인수의 데이터 타입이 유효하지 않을 때 발생하는 에러 객체         |
  | RangeError     | 숫자값의 허용 범위를 벗어났을 때 발생하는 에러 객체                            |
  | URIError       | encodeURI 또는 decodeURI 함수에 부적절한 인수를 전달했을 때 발생하는 에러 객체 |
  | EvalError      | eval 함수에서 발생하는 에러 객체                                               |

## 47.4 throw 문

- Error 생성자 함수로 에러 객체를 생성한다고 에러가 발생하는 것은 아니다.
- 에러 객체 생성과 에러 발생은 의미가 다르다.
- 에러를 `발생`시키려면 try 코드 블록에서 throw문으로 에러 객체를 던져야 한다.
- 에러를 던지면 catch 문의 에러 변수가 생성되고 던져진 에러 객체가 할당된다.
- 그리고 catch 코드 블록이 실행되기 시작한다.

```js
// 외부에서 전달받은 콜백 함수를 n번만큼 반복 호출한다
const repeat = (n, f) => {
  // 매개변수 f에 전달된 인수가 함수가 아니면 TypeError를 발생시킨다.
  if (typeof f !== "function") throw new TypeError("f must be a function");

  for (var i = 0; i < n; i++) {
    f(i); // i를 전달하면서 f를 호출
  }
};

try {
  repeat(2, 1); // 두 번째 인수가 함수가 아니므로 TypeError가 발생(throw)한다.
} catch (err) {
  console.error(err); // TypeError: f must be a function
}
```

## 47.5 에러의 전파

- 에러는 호출자 방향으로 전파된다.
- 즉, 실행 중인 실행 컨텍스트가 푸시괴지 직전에 푸시된 실행 컨텍스트 방향으로 전파된다.

```js
const foo = () => {
  throw Error("foo에서 발생한 에러"); // ④
};

const bar = () => {
  foo(); // ③
};

const baz = () => {
  bar(); // ②
};

try {
  baz(); // ①
} catch (err) {
  console.error(err);
}
```

- 4 -> 3 -> 2 -> 1 -> 전역에서 캐치된다.
- throw를 catch하여 적절한 대처를 만들어 두면 프로그램이 강제 종료되지 않는다.

## 💡 비동기 함수의 에러 처리

- 비동기 함수인 setTimeout이나 프로미스 후속 처리 메서드의 콜백 함수는 호출자가 없다.
- 따라서 이러한 비동기 콜백 내에서 발생하는 에러는 호출 스택을 통한 일반적인 에러 전파와는 다르게 처리되어야 한다.

### 1. 비동기 콜백 내에서의 에러 처리

- 비동기 콜백 내에서 발생하는 에러는 그 콜백 외부의 try...catch로 잡히지 않는다.
- 따라서 각 **비동기 콜백 내**에서 에러 처리를 수행해야 한다.

```js
// 잘못된 예
try {
  setTimeout(() => {
    throw new Error("에러 발생!");
  }, 1000);
} catch (err) {
  console.error("에러 처리:", err);
}

// 올바른 예
setTimeout(() => {
  try {
    throw new Error("에러 발생!");
  } catch (err) {
    console.error("에러 처리:", err);
  }
}, 1000);
```

### 2. 프로미스 체인의 에러 처리

- then 또는 catch `콜백 내`에서 발생하는 에러는 체인의 다음 catch에서 잡힌다.
- 그러나 마지막 catch에서 발생하는 에러는 처리되지 않는다.
- 따라서 항상 프로미스 체인의 마지막에 catch를 추가하여 잠재적인 에러를 처리해야 한다.

```js
Promise.resolve()
  .then(() => {
    throw new Error("첫 번째 에러!");
  })
  .catch((err) => {
    console.error("에러 처리:", err);
    throw new Error("두 번째 에러!");
  })
  .catch((err) => {
    console.error("또 다른 에러 처리:", err);
  });
```

### `fetch`에서 catch로 잡히지 않는 에러 `404`, `500`

- fetch 함수가 반환하는 프로미스는 HTTP 응답 자체가 실패하거나 네트워크 요청 자체가 중단되지 않는 한 거부(rejected) 상태가 되지 않는다.
- 즉, HTTP 상태 코드가 404나 500 같은 에러 상태라 해도, fetch는 이를 "성공적인 HTTP 응답"으로 간주하고 프로미스는 이행(fulfilled) 상태가 된다.
- 그렇기 때문에, fetch를 사용한다면 HTTP 응답의 상태 코드를 확인하고 에러 처리를 직접 구현해야 한다.

```js
fetch("/api/data")
  .then((response) => {
    if (!response.ok) {
      throw new Error(`HTTP error! Status: ${response.status}`);
    }
    return response.json();
  })
  .then((data) => {
    console.log(data);
  })
  .catch((error) => {
    console.error("Fetch error:", error.message);
  });
```

- 위의 코드에서 response.ok는 HTTP 상태 코드가 200-299 범위인지 확인하는 데 사용된다.
- 만약 그 범위를 벗어나면 에러를 던져서 .catch 블록에서 처리할 수 있게 된다.
